<mujoco model="rrbot_arm_box">
  <asset>
    <texture name="skybox" type="skybox" builtin="gradient" rgb1=".2 .3 .4" rgb2="0 0 0" width="800" height="800" mark="random" markrgb="1 1 1" />
    <texture name="grid" type="2d" builtin="checker" rgb1=".2 .1 .2" rgb2=".3 .2 .3" width="300" height="300" mark="edge" markrgb=".3 .2 .3" />
    <material name="grid" texture="grid" texrepeat="1 1" texuniform="true" reflectance=".2" />
    <material name="self" rgba=".7 .5 .3 1" />
  </asset>
  <visual>
    <headlight ambient=".4 .4 .4" diffuse=".8 .8 .8" specular="0 0 0" />
    <map znear=".001" />
    <quality shadowsize="16384" />
  </visual>
  <compiler angle="degree" />
  <option integrator="RK4" timestep="0.01" />
  <default>
    <joint armature="1" damping="1" limited="true" />
    <geom conaffinity="0" condim="3" density="5.0" friction="1.0 0.5 0.5" margin="0.01" />
  </default>
  <worldbody>
    <light cutoff="100" diffuse="1 1 1" dir="0.3 0 -1.3" directional="true" exponent="1" pos="-30 0 130" specular=".1 .1 .1" />
    <geom conaffinity="1" condim="3" name="floor" pos="0 0 0" rgba="1 1 1 1" size="200 200 .125" type="plane" />
    <!-- Fixed-base 2-joint arm with box visual geoms (verification 2+3).
         capsule: physics proxy (transparent), drives bone_offset
         box:     visual shape (no collision), synced by _sync_visual_geoms() -->
    <body name="0" pos="0 0 0">
      <camera name="track" mode="trackcom" pos="0 -3 0.3" xyaxes="1 0 0 0 0 1" />
      <geom pos="0 0 0" size="0.12" type="sphere" rgba=".4 .4 .4 1" />
      <!-- no free joint: fixed to world -->
      <body name="1" pos="0 0 0">
        <joint axis="0 0 1" name="1_joint" pos="0 0 0" range="-60 60" type="hinge" />
        <!-- physics capsule (invisible) -->
        <geom fromto="0 0 0 0.3 0 0" size="0.05" type="capsule" rgba="0 0 0 0" contype="1" conaffinity="1" />
        <!-- visual box (no collision) — pos/size updated by _sync_visual_geoms() -->
        <geom type="box" pos="0.15 0 0" size="0.15 0.04 0.04" rgba="0.2 0.6 0.9 1" contype="0" conaffinity="0" />
        <!-- body name "11" = reindex(1st child of "1") -->
        <body name="11" pos="0.3 0 0">
          <joint axis="0 0 1" name="11_joint" pos="0 0 0" range="-90 90" type="hinge" />
          <!-- physics capsule (invisible) -->
          <geom fromto="0 0 0 0.25 0 0" size="0.04" type="capsule" rgba="0 0 0 0" contype="1" conaffinity="1" />
          <!-- visual box (no collision) -->
          <geom type="box" pos="0.125 0 0" size="0.125 0.035 0.035" rgba="0.9 0.5 0.1 1" contype="0" conaffinity="0" />
        </body>
      </body>
    </body>
    <body name="cube" pos="0 0 0">
      <joint name="cube_slide" type="slide" axis="1 0 0" pos="1.2 0 1.02" damping="5.0" range="0  200" />
      <joint name="cube_slide2" type="slide" axis="0 1 0" pos="1.2 0 1.02" damping="5.0" range="-100  100" />
      <geom pos="1.2 0 1.02" name="cube_geom" type="box" size="1.0 1.0 1.0" rgba="0.8 0.2 0.2 0.6" friction="0 0 0" density="1" contype="1" conaffinity="1" />
    </body>
  </worldbody>
  <actuator>
    <motor ctrllimited="true" ctrlrange="-1.0 1.0" joint="1_joint" gear="150" name="1_joint" />
    <motor ctrllimited="true" ctrlrange="-1.0 1.0" joint="11_joint" gear="100" name="11_joint" />
  </actuator>
</mujoco>
