<mujoco model="3-joint_serial_arm_(from_mesh)">
  <asset>
    <texture name="skybox" type="skybox" builtin="gradient" rgb1=".2 .3 .4" rgb2="0 0 0" width="800" height="800" mark="random" markrgb="1 1 1"/>
    <texture name="grid" type="2d" builtin="checker" rgb1=".2 .1 .2" rgb2=".3 .2 .3" width="300" height="300" mark="edge" markrgb=".3 .2 .3"/>
    <material name="grid" texture="grid" texrepeat="1 1" texuniform="true" reflectance=".2"/>
    <material name="self" rgba=".7 .5 .3 1"/>
  </asset>
  <visual>
    <headlight ambient=".4 .4 .4" diffuse=".8 .8 .8" specular="0 0 0"/>
    <map znear=".001"/>
    <quality shadowsize="16384"/>
  </visual>
  <compiler angle="degree"/>
  <option integrator="RK4" timestep="0.01"/>
  <default>
    <joint armature="1" damping="1" limited="true"/>
    <geom conaffinity="0" condim="3" density="5.0" friction="1.0 0.5 0.5" margin="0.01" rgba=".7 .5 .3 1"/>
  </default>
  <worldbody>
    <light cutoff="100" diffuse="1 1 1" dir="0.3 0 -1.3" directional="true" exponent="1" pos="-30 0 130" specular=".1 .1 .1"/>
    <geom conaffinity="1" condim="3" name="floor" pos="0 0 0" rgba="1 1 1 1" size="200 200 .125" type="plane" material="grid"/>
    <body name="0" pos="0.000000 0.000000 0.150000">
      <camera name="track" mode="trackcom" pos="0 -3 0.3" xyaxes="1 0 0 0 0 1"/>
      <geom pos="0 0 0" size="0.1" type="sphere"/>
      <body name="1" pos="0.000000 0.000000 0.000000">
        <joint name="1_joint" type="hinge" pos="0 0 0" axis="0.000000 0.000000 1.000000" range="-60.0 60.0"/>
        <geom type="capsule" fromto="0.000000 0.000000 0.000000  0.303700 0.000000 0.000000" size="0.045"/>
        <body name="11" pos="0.303700 0.000000 0.000000">
          <joint name="11_joint" type="hinge" pos="0 0 0" axis="0.000000 0.000000 1.000000" range="-90.0 90.0"/>
          <geom type="capsule" fromto="0.000000 0.000000 0.000000  0.299100 0.000000 0.000000" size="0.0326"/>
          <body name="111" pos="0.299100 0.000000 0.000000">
            <joint name="111_joint" type="hinge" pos="0 0 0" axis="0.000000 0.000000 1.000000" range="-45.0 45.0"/>
            <geom type="capsule" fromto="0.000000 0.000000 0.000000  0.203400 0.000000 0.000000" size="0.032"/>
          </body>
        </body>
      </body>
    </body>
    <body name="cube" pos="1.000000 0.000000 0.200000">
      <joint name="cube_slide" type="slide" axis="1 0 0" damping="2.0" range="-2.0 200.0"/>
      <joint name="cube_slide2" type="slide" axis="0 1 0" damping="2.0" range="-100.0 100.0"/>
      <geom name="cube_geom" type="box" size="0.15 0.15 0.15" rgba="0.8 0.2 0.2 1.0" friction="0.5 0.1 0.1" density="100" contype="1" conaffinity="1"/>
    </body>
  </worldbody>
  <actuator>
    <motor ctrllimited="true" ctrlrange="-1.0 1.0" joint="1_joint" gear="150.0" name="1_joint"/>
    <motor ctrllimited="true" ctrlrange="-1.0 1.0" joint="11_joint" gear="100.0" name="11_joint"/>
    <motor ctrllimited="true" ctrlrange="-1.0 1.0" joint="111_joint" gear="80.0" name="111_joint"/>
  </actuator>
</mujoco>
